[2025-05-21T20:08:40.839+0530] {local_task_job_runner.py:123} INFO - ::group::Pre task execution logs
[2025-05-21T20:08:40.847+0530] {taskinstance.py:2612} INFO - Dependencies all met for dep_context=non-requeueable deps ti=<TaskInstance: airbyte_sync_dag.trigger_airbyte_sync manual__2025-05-21T14:38:16.304156+00:00 [queued]>
[2025-05-21T20:08:40.854+0530] {taskinstance.py:2612} INFO - Dependencies all met for dep_context=requeueable deps ti=<TaskInstance: airbyte_sync_dag.trigger_airbyte_sync manual__2025-05-21T14:38:16.304156+00:00 [queued]>
[2025-05-21T20:08:40.854+0530] {taskinstance.py:2865} INFO - Starting attempt 1 of 1
[2025-05-21T20:08:40.870+0530] {taskinstance.py:2888} INFO - Executing <Task(AirbyteTriggerSyncOperator): trigger_airbyte_sync> on 2025-05-21 14:38:16.304156+00:00
[2025-05-21T20:08:40.872+0530] {standard_task_runner.py:72} INFO - Started process 97743 to run task
[2025-05-21T20:08:40.875+0530] {standard_task_runner.py:104} INFO - Running: ['airflow', 'tasks', 'run', 'airbyte_sync_dag', 'trigger_airbyte_sync', 'manual__2025-05-21T14:38:16.304156+00:00', '--job-id', '109', '--raw', '--subdir', 'DAGS_FOLDER/airbyte_dag.py', '--cfg-path', '/tmp/tmpegvhhs_8']
[2025-05-21T20:08:40.877+0530] {standard_task_runner.py:105} INFO - Job 109: Subtask trigger_airbyte_sync
[2025-05-21T20:08:40.903+0530] {task_command.py:467} INFO - Running <TaskInstance: airbyte_sync_dag.trigger_airbyte_sync manual__2025-05-21T14:38:16.304156+00:00 [running]> on host Voldemort.
[2025-05-21T20:08:40.954+0530] {taskinstance.py:3131} INFO - Exporting env vars: AIRFLOW_CTX_DAG_OWNER='airflow' AIRFLOW_CTX_DAG_ID='airbyte_sync_dag' AIRFLOW_CTX_TASK_ID='trigger_airbyte_sync' AIRFLOW_CTX_EXECUTION_DATE='2025-05-21T14:38:16.304156+00:00' AIRFLOW_CTX_TRY_NUMBER='1' AIRFLOW_CTX_DAG_RUN_ID='manual__2025-05-21T14:38:16.304156+00:00'
[2025-05-21T20:08:40.955+0530] {taskinstance.py:731} INFO - ::endgroup::
[2025-05-21T20:08:40.969+0530] {base.py:84} INFO - Retrieving connection 'airbyte_cloud'
[2025-05-21T20:08:43.261+0530] {airbyte.py:89} INFO - Job 37164524 was submitted to Airbyte Server
[2025-05-21T20:09:08.433+0530] {taskinstance.py:3310} ERROR - Task failed with exception
Traceback (most recent call last):
  File "/home/pranav_shirali/airflow-project/airflow-env/lib/python3.10/site-packages/airflow/models/taskinstance.py", line 767, in _execute_task
    result = _execute_callable(context=context, **execute_callable_kwargs)
  File "/home/pranav_shirali/airflow-project/airflow-env/lib/python3.10/site-packages/airflow/models/taskinstance.py", line 733, in _execute_callable
    return ExecutionCallableRunner(
  File "/home/pranav_shirali/airflow-project/airflow-env/lib/python3.10/site-packages/airflow/utils/operator_helpers.py", line 252, in run
    return self.func(*args, **kwargs)
  File "/home/pranav_shirali/airflow-project/airflow-env/lib/python3.10/site-packages/airflow/models/baseoperator.py", line 406, in wrapper
    return func(self, *args, **kwargs)
  File "/home/pranav_shirali/airflow-project/airflow-env/lib/python3.10/site-packages/airflow/providers/airbyte/operators/airbyte.py", line 96, in execute
    hook.wait_for_job(job_id=self.job_id, wait_seconds=self.wait_seconds, timeout=self.timeout)
  File "/home/pranav_shirali/airflow-project/airflow-env/lib/python3.10/site-packages/airflow/providers/airbyte/hooks/airbyte.py", line 151, in wait_for_job
    raise AirflowException(f"Job was cancelled:\n{job}")
airflow.exceptions.AirflowException: Job was cancelled:
JobResponse(connection_id='83fc1990-66cb-4776-809d-0efc2811acb3', job_id=37164524, job_type=<JobTypeEnum.SYNC: 'sync'>, start_time='2025-05-21T14:38:44Z', status=<JobStatusEnum.CANCELLED: 'cancelled'>, bytes_synced=0, duration='PT24S', last_updated_at='2025-05-21T14:39:08Z', rows_synced=0)
[2025-05-21T20:09:08.435+0530] {taskinstance.py:1225} INFO - Marking task as FAILED. dag_id=airbyte_sync_dag, task_id=trigger_airbyte_sync, run_id=manual__2025-05-21T14:38:16.304156+00:00, execution_date=20250521T143816, start_date=20250521T143840, end_date=20250521T143908
[2025-05-21T20:09:08.445+0530] {taskinstance.py:340} INFO - ::group::Post task execution logs
[2025-05-21T20:09:08.445+0530] {standard_task_runner.py:124} ERROR - Failed to execute job 109 for task trigger_airbyte_sync (Job was cancelled:
JobResponse(connection_id='83fc1990-66cb-4776-809d-0efc2811acb3', job_id=37164524, job_type=<JobTypeEnum.SYNC: 'sync'>, start_time='2025-05-21T14:38:44Z', status=<JobStatusEnum.CANCELLED: 'cancelled'>, bytes_synced=0, duration='PT24S', last_updated_at='2025-05-21T14:39:08Z', rows_synced=0); 97743)
Traceback (most recent call last):
  File "/home/pranav_shirali/airflow-project/airflow-env/lib/python3.10/site-packages/airflow/task/task_runner/standard_task_runner.py", line 117, in _start_by_fork
    ret = args.func(args, dag=self.dag)
  File "/home/pranav_shirali/airflow-project/airflow-env/lib/python3.10/site-packages/airflow/cli/cli_config.py", line 49, in command
    return func(*args, **kwargs)
  File "/home/pranav_shirali/airflow-project/airflow-env/lib/python3.10/site-packages/airflow/utils/cli.py", line 115, in wrapper
    return f(*args, **kwargs)
  File "/home/pranav_shirali/airflow-project/airflow-env/lib/python3.10/site-packages/airflow/cli/commands/task_command.py", line 483, in task_run
    task_return_code = _run_task_by_selected_method(args, _dag, ti)
  File "/home/pranav_shirali/airflow-project/airflow-env/lib/python3.10/site-packages/airflow/cli/commands/task_command.py", line 256, in _run_task_by_selected_method
    return _run_raw_task(args, ti)
  File "/home/pranav_shirali/airflow-project/airflow-env/lib/python3.10/site-packages/airflow/cli/commands/task_command.py", line 341, in _run_raw_task
    return ti._run_raw_task(
  File "/home/pranav_shirali/airflow-project/airflow-env/lib/python3.10/site-packages/airflow/utils/session.py", line 97, in wrapper
    return func(*args, session=session, **kwargs)
  File "/home/pranav_shirali/airflow-project/airflow-env/lib/python3.10/site-packages/airflow/models/taskinstance.py", line 3004, in _run_raw_task
    return _run_raw_task(
  File "/home/pranav_shirali/airflow-project/airflow-env/lib/python3.10/site-packages/airflow/models/taskinstance.py", line 273, in _run_raw_task
    TaskInstance._execute_task_with_callbacks(
  File "/home/pranav_shirali/airflow-project/airflow-env/lib/python3.10/site-packages/airflow/models/taskinstance.py", line 3158, in _execute_task_with_callbacks
    result = self._execute_task(context, task_orig)
  File "/home/pranav_shirali/airflow-project/airflow-env/lib/python3.10/site-packages/airflow/models/taskinstance.py", line 3182, in _execute_task
    return _execute_task(self, context, task_orig)
  File "/home/pranav_shirali/airflow-project/airflow-env/lib/python3.10/site-packages/airflow/models/taskinstance.py", line 767, in _execute_task
    result = _execute_callable(context=context, **execute_callable_kwargs)
  File "/home/pranav_shirali/airflow-project/airflow-env/lib/python3.10/site-packages/airflow/models/taskinstance.py", line 733, in _execute_callable
    return ExecutionCallableRunner(
  File "/home/pranav_shirali/airflow-project/airflow-env/lib/python3.10/site-packages/airflow/utils/operator_helpers.py", line 252, in run
    return self.func(*args, **kwargs)
  File "/home/pranav_shirali/airflow-project/airflow-env/lib/python3.10/site-packages/airflow/models/baseoperator.py", line 406, in wrapper
    return func(self, *args, **kwargs)
  File "/home/pranav_shirali/airflow-project/airflow-env/lib/python3.10/site-packages/airflow/providers/airbyte/operators/airbyte.py", line 96, in execute
    hook.wait_for_job(job_id=self.job_id, wait_seconds=self.wait_seconds, timeout=self.timeout)
  File "/home/pranav_shirali/airflow-project/airflow-env/lib/python3.10/site-packages/airflow/providers/airbyte/hooks/airbyte.py", line 151, in wait_for_job
    raise AirflowException(f"Job was cancelled:\n{job}")
airflow.exceptions.AirflowException: Job was cancelled:
JobResponse(connection_id='83fc1990-66cb-4776-809d-0efc2811acb3', job_id=37164524, job_type=<JobTypeEnum.SYNC: 'sync'>, start_time='2025-05-21T14:38:44Z', status=<JobStatusEnum.CANCELLED: 'cancelled'>, bytes_synced=0, duration='PT24S', last_updated_at='2025-05-21T14:39:08Z', rows_synced=0)
[2025-05-21T20:09:08.488+0530] {local_task_job_runner.py:266} INFO - Task exited with return code 1
[2025-05-21T20:09:08.498+0530] {taskinstance.py:3900} INFO - 0 downstream tasks scheduled from follow-on schedule check
[2025-05-21T20:09:08.503+0530] {local_task_job_runner.py:245} INFO - ::endgroup::
