[2025-05-23T11:27:30.357+0530] {local_task_job_runner.py:123} INFO - ::group::Pre task execution logs
[2025-05-23T11:27:30.365+0530] {taskinstance.py:2612} INFO - Dependencies all met for dep_context=non-requeueable deps ti=<TaskInstance: elt_sales_stream_transformation.transform_sales_stream manual__2025-05-23T05:57:27.667545+00:00 [queued]>
[2025-05-23T11:27:30.369+0530] {taskinstance.py:2612} INFO - Dependencies all met for dep_context=requeueable deps ti=<TaskInstance: elt_sales_stream_transformation.transform_sales_stream manual__2025-05-23T05:57:27.667545+00:00 [queued]>
[2025-05-23T11:27:30.369+0530] {taskinstance.py:2865} INFO - Starting attempt 1 of 1
[2025-05-23T11:27:30.380+0530] {taskinstance.py:2888} INFO - Executing <Task(SQLExecuteQueryOperator): transform_sales_stream> on 2025-05-23 05:57:27.667545+00:00
[2025-05-23T11:27:30.383+0530] {standard_task_runner.py:72} INFO - Started process 8813 to run task
[2025-05-23T11:27:30.386+0530] {standard_task_runner.py:104} INFO - Running: ['airflow', 'tasks', 'run', 'elt_sales_stream_transformation', 'transform_sales_stream', 'manual__2025-05-23T05:57:27.667545+00:00', '--job-id', '165', '--raw', '--subdir', 'DAGS_FOLDER/elt_transformation_dag.py', '--cfg-path', '/tmp/tmp_9tfvhrs']
[2025-05-23T11:27:30.387+0530] {standard_task_runner.py:105} INFO - Job 165: Subtask transform_sales_stream
[2025-05-23T11:27:30.412+0530] {task_command.py:467} INFO - Running <TaskInstance: elt_sales_stream_transformation.transform_sales_stream manual__2025-05-23T05:57:27.667545+00:00 [running]> on host Voldemort.
[2025-05-23T11:27:30.458+0530] {taskinstance.py:3131} INFO - Exporting env vars: AIRFLOW_CTX_DAG_OWNER='airflow' AIRFLOW_CTX_DAG_ID='elt_sales_stream_transformation' AIRFLOW_CTX_TASK_ID='transform_sales_stream' AIRFLOW_CTX_EXECUTION_DATE='2025-05-23T05:57:27.667545+00:00' AIRFLOW_CTX_TRY_NUMBER='1' AIRFLOW_CTX_DAG_RUN_ID='manual__2025-05-23T05:57:27.667545+00:00'
[2025-05-23T11:27:30.459+0530] {taskinstance.py:731} INFO - ::endgroup::
[2025-05-23T11:27:30.469+0530] {sql.py:306} INFO - Executing: 
        CREATE OR REPLACE TABLE AIRFLOW_DB.PUBLIC.SALES_STREAM_TRANSFORMED AS
        SELECT
            REGION,
            COUNTRY,
            "ITEM TYPE",
            "SALES CHANNEL",
            "ORDER PRIORITY",
            "ORDER DATE",
            "ORDER ID",
            "SHIP DATE",
            "UNITS SOLD",
            "UNIT PRICE",
            "UNIT COST",
            "TOTAL REVENUE",
            "TOTAL COST",
            "TOTAL PROFIT",
            CASE
                WHEN "ORDER PRIORITY" = 'H' THEN 'High'
                WHEN "ORDER PRIORITY" = 'L' THEN 'Low'
                WHEN "ORDER PRIORITY" = 'M' THEN 'Medium'
                WHEN "ORDER PRIORITY" = 'C' THEN 'Cold'
                ELSE "ORDER PRIORITY"
            END AS "ORDER_PRIORITY_DESC",
            DATEDIFF(
                'day',
                COALESCE(
                  TRY_TO_DATE("ORDER DATE", 'M/D/YYYY'),
                  TRY_TO_DATE("ORDER DATE", 'MM/DD/YYYY'),
                  TRY_TO_DATE("ORDER DATE", 'YYYY-MM-DD')
                ),
                COALESCE(
                  TRY_TO_DATE("SHIP DATE", 'M/D/YYYY'),
                  TRY_TO_DATE("SHIP DATE", 'MM/DD/YYYY'),
                  TRY_TO_DATE("SHIP DATE", 'YYYY-MM-DD')
                )
            ) AS "SHIPMENT_LEAD_TIME"
        FROM AIRFLOW_DB.PUBLIC."SALES STREAM";
        
[2025-05-23T11:27:30.473+0530] {base.py:84} INFO - Retrieving connection 'snowflake_con'
[2025-05-23T11:27:30.490+0530] {base.py:84} INFO - Retrieving connection 'snowflake_con'
[2025-05-23T11:27:30.490+0530] {connection.py:486} INFO - Snowflake Connector for Python Version: 3.15.0, Python Version: 3.10.12, Platform: Linux-5.15.167.4-microsoft-standard-WSL2-x86_64-with-glibc2.35
[2025-05-23T11:27:30.491+0530] {connection.py:1391} INFO - Connecting to GLOBAL Snowflake domain
[2025-05-23T11:27:31.404+0530] {connection.py:547} WARNING - Certificate did not match expected hostname: avcudfk-tl56570.ap_southeast_1.snowflakecomputing.com. Certificate: {'subject': ((('commonName', '*.prod3.us-west-2.snowflakecomputing.com'),),), 'subjectAltName': [('DNS', '*.prod3.us-west-2.snowflakecomputing.com'), ('DNS', '*.us-west-2.snowflakecomputing.com'), ('DNS', '*.global.snowflakecomputing.com'), ('DNS', '*.snowflakecomputing.com'), ('DNS', '*.prod3.us-west-2.aws.snowflakecomputing.com')]}
[2025-05-23T11:27:31.405+0530] {connectionpool.py:824} WARNING - Retrying (Retry(total=0, connect=None, read=None, redirect=None, status=None)) after connection broken by 'SSLError(CertificateError("hostname 'avcudfk-tl56570.ap_southeast_1.snowflakecomputing.com' doesn't match either of '*.prod3.us-west-2.snowflakecomputing.com', '*.us-west-2.snowflakecomputing.com', '*.global.snowflakecomputing.com', '*.snowflakecomputing.com', '*.prod3.us-west-2.aws.snowflakecomputing.com'"))': /session/v1/login-request?request_id=81c11043-deeb-48f2-8025-8d7aacb412cb&databaseName=AIRFLOW_DB&schemaName=PUBLIC&warehouse=AIRFLOW_WH&roleName=ACCOUNTADMIN&request_guid=7cd2ff1b-6590-46f5-983c-83280e431eb2
[2025-05-23T11:27:32.128+0530] {connection.py:547} WARNING - Certificate did not match expected hostname: avcudfk-tl56570.ap_southeast_1.snowflakecomputing.com. Certificate: {'subject': ((('commonName', '*.prod3.us-west-2.snowflakecomputing.com'),),), 'subjectAltName': [('DNS', '*.prod3.us-west-2.snowflakecomputing.com'), ('DNS', '*.us-west-2.snowflakecomputing.com'), ('DNS', '*.global.snowflakecomputing.com'), ('DNS', '*.snowflakecomputing.com'), ('DNS', '*.prod3.us-west-2.aws.snowflakecomputing.com')]}
[2025-05-23T11:27:33.817+0530] {connection.py:547} WARNING - Certificate did not match expected hostname: avcudfk-tl56570.ap_southeast_1.snowflakecomputing.com. Certificate: {'subject': ((('commonName', '*.prod3.us-west-2.snowflakecomputing.com'),),), 'subjectAltName': [('DNS', '*.prod3.us-west-2.snowflakecomputing.com'), ('DNS', '*.us-west-2.snowflakecomputing.com'), ('DNS', '*.global.snowflakecomputing.com'), ('DNS', '*.snowflakecomputing.com'), ('DNS', '*.prod3.us-west-2.aws.snowflakecomputing.com')]}
[2025-05-23T11:27:33.817+0530] {connectionpool.py:824} WARNING - Retrying (Retry(total=0, connect=None, read=None, redirect=None, status=None)) after connection broken by 'SSLError(CertificateError("hostname 'avcudfk-tl56570.ap_southeast_1.snowflakecomputing.com' doesn't match either of '*.prod3.us-west-2.snowflakecomputing.com', '*.us-west-2.snowflakecomputing.com', '*.global.snowflakecomputing.com', '*.snowflakecomputing.com', '*.prod3.us-west-2.aws.snowflakecomputing.com'"))': /session/v1/login-request?request_id=7abfdd5f-676d-4c7d-9720-e77321da2a3e&databaseName=AIRFLOW_DB&schemaName=PUBLIC&warehouse=AIRFLOW_WH&roleName=ACCOUNTADMIN&request_guid=c12759c7-65e1-4518-b415-aef89c517ec2
[2025-05-23T11:27:34.502+0530] {connection.py:547} WARNING - Certificate did not match expected hostname: avcudfk-tl56570.ap_southeast_1.snowflakecomputing.com. Certificate: {'subject': ((('commonName', '*.prod3.us-west-2.snowflakecomputing.com'),),), 'subjectAltName': [('DNS', '*.prod3.us-west-2.snowflakecomputing.com'), ('DNS', '*.us-west-2.snowflakecomputing.com'), ('DNS', '*.global.snowflakecomputing.com'), ('DNS', '*.snowflakecomputing.com'), ('DNS', '*.prod3.us-west-2.aws.snowflakecomputing.com')]}
[2025-05-23T11:27:34.506+0530] {taskinstance.py:3310} ERROR - Task failed with exception
Traceback (most recent call last):
  File "/home/pranav_shirali/airflow-project/airflow-env/lib/python3.10/site-packages/snowflake/connector/vendored/urllib3/connectionpool.py", line 715, in urlopen
    httplib_response = self._make_request(
  File "/home/pranav_shirali/airflow-project/airflow-env/lib/python3.10/site-packages/snowflake/connector/vendored/urllib3/connectionpool.py", line 404, in _make_request
    self._validate_conn(conn)
  File "/home/pranav_shirali/airflow-project/airflow-env/lib/python3.10/site-packages/snowflake/connector/vendored/urllib3/connectionpool.py", line 1058, in _validate_conn
    conn.connect()
  File "/home/pranav_shirali/airflow-project/airflow-env/lib/python3.10/site-packages/snowflake/connector/vendored/urllib3/connection.py", line 472, in connect
    _match_hostname(cert, self.assert_hostname or server_hostname)
  File "/home/pranav_shirali/airflow-project/airflow-env/lib/python3.10/site-packages/snowflake/connector/vendored/urllib3/connection.py", line 545, in _match_hostname
    match_hostname(cert, asserted_hostname)
  File "/home/pranav_shirali/airflow-project/airflow-env/lib/python3.10/site-packages/snowflake/connector/vendored/urllib3/util/ssl_match_hostname.py", line 150, in match_hostname
    raise CertificateError(
snowflake.connector.vendored.urllib3.util.ssl_match_hostname.CertificateError: hostname 'avcudfk-tl56570.ap_southeast_1.snowflakecomputing.com' doesn't match either of '*.prod3.us-west-2.snowflakecomputing.com', '*.us-west-2.snowflakecomputing.com', '*.global.snowflakecomputing.com', '*.snowflakecomputing.com', '*.prod3.us-west-2.aws.snowflakecomputing.com'

During handling of the above exception, another exception occurred:

Traceback (most recent call last):
  File "/home/pranav_shirali/airflow-project/airflow-env/lib/python3.10/site-packages/snowflake/connector/vendored/requests/adapters.py", line 485, in send
    resp = conn.urlopen(
  File "/home/pranav_shirali/airflow-project/airflow-env/lib/python3.10/site-packages/snowflake/connector/vendored/urllib3/connectionpool.py", line 827, in urlopen
    return self.urlopen(
  File "/home/pranav_shirali/airflow-project/airflow-env/lib/python3.10/site-packages/snowflake/connector/vendored/urllib3/connectionpool.py", line 799, in urlopen
    retries = retries.increment(
  File "/home/pranav_shirali/airflow-project/airflow-env/lib/python3.10/site-packages/snowflake/connector/vendored/urllib3/util/retry.py", line 592, in increment
    raise MaxRetryError(_pool, url, error or ResponseError(cause))
snowflake.connector.vendored.urllib3.exceptions.MaxRetryError: HTTPSConnectionPool(host='avcudfk-tl56570.ap_southeast_1.snowflakecomputing.com', port=443): Max retries exceeded with url: /session/v1/login-request?request_id=81c11043-deeb-48f2-8025-8d7aacb412cb&databaseName=AIRFLOW_DB&schemaName=PUBLIC&warehouse=AIRFLOW_WH&roleName=ACCOUNTADMIN&request_guid=7cd2ff1b-6590-46f5-983c-83280e431eb2 (Caused by SSLError(CertificateError("hostname 'avcudfk-tl56570.ap_southeast_1.snowflakecomputing.com' doesn't match either of '*.prod3.us-west-2.snowflakecomputing.com', '*.us-west-2.snowflakecomputing.com', '*.global.snowflakecomputing.com', '*.snowflakecomputing.com', '*.prod3.us-west-2.aws.snowflakecomputing.com'")))

During handling of the above exception, another exception occurred:

Traceback (most recent call last):
  File "/home/pranav_shirali/airflow-project/airflow-env/lib/python3.10/site-packages/snowflake/connector/network.py", line 1091, in _request_exec
    raw_ret = session.request(
  File "/home/pranav_shirali/airflow-project/airflow-env/lib/python3.10/site-packages/snowflake/connector/vendored/requests/sessions.py", line 589, in request
    resp = self.send(prep, **send_kwargs)
  File "/home/pranav_shirali/airflow-project/airflow-env/lib/python3.10/site-packages/snowflake/connector/vendored/requests/sessions.py", line 703, in send
    r = adapter.send(request, **kwargs)
  File "/home/pranav_shirali/airflow-project/airflow-env/lib/python3.10/site-packages/snowflake/connector/vendored/requests/adapters.py", line 516, in send
    raise SSLError(e, request=request)
snowflake.connector.vendored.requests.exceptions.SSLError: HTTPSConnectionPool(host='avcudfk-tl56570.ap_southeast_1.snowflakecomputing.com', port=443): Max retries exceeded with url: /session/v1/login-request?request_id=81c11043-deeb-48f2-8025-8d7aacb412cb&databaseName=AIRFLOW_DB&schemaName=PUBLIC&warehouse=AIRFLOW_WH&roleName=ACCOUNTADMIN&request_guid=7cd2ff1b-6590-46f5-983c-83280e431eb2 (Caused by SSLError(CertificateError("hostname 'avcudfk-tl56570.ap_southeast_1.snowflakecomputing.com' doesn't match either of '*.prod3.us-west-2.snowflakecomputing.com', '*.us-west-2.snowflakecomputing.com', '*.global.snowflakecomputing.com', '*.snowflakecomputing.com', '*.prod3.us-west-2.aws.snowflakecomputing.com'")))

During handling of the above exception, another exception occurred:

Traceback (most recent call last):
  File "/home/pranav_shirali/airflow-project/airflow-env/lib/python3.10/site-packages/snowflake/connector/connection.py", line 1647, in _authenticate
    auth.authenticate(
  File "/home/pranav_shirali/airflow-project/airflow-env/lib/python3.10/site-packages/snowflake/connector/auth/_auth.py", line 226, in authenticate
    ret = self._rest._post_request(
  File "/home/pranav_shirali/airflow-project/airflow-env/lib/python3.10/site-packages/snowflake/connector/network.py", line 759, in _post_request
    ret = self.fetch(
  File "/home/pranav_shirali/airflow-project/airflow-env/lib/python3.10/site-packages/snowflake/connector/network.py", line 874, in fetch
    ret = self._request_exec_wrapper(
  File "/home/pranav_shirali/airflow-project/airflow-env/lib/python3.10/site-packages/snowflake/connector/network.py", line 1002, in _request_exec_wrapper
    raise e
  File "/home/pranav_shirali/airflow-project/airflow-env/lib/python3.10/site-packages/snowflake/connector/network.py", line 924, in _request_exec_wrapper
    return_object = self._request_exec(
  File "/home/pranav_shirali/airflow-project/airflow-env/lib/python3.10/site-packages/snowflake/connector/network.py", line 1161, in _request_exec
    Error.errorhandler_wrapper(
  File "/home/pranav_shirali/airflow-project/airflow-env/lib/python3.10/site-packages/snowflake/connector/errors.py", line 279, in errorhandler_wrapper
    handed_over = Error.hand_to_other_handler(
  File "/home/pranav_shirali/airflow-project/airflow-env/lib/python3.10/site-packages/snowflake/connector/errors.py", line 337, in hand_to_other_handler
    connection.errorhandler(connection, cursor, error_class, error_value)
  File "/home/pranav_shirali/airflow-project/airflow-env/lib/python3.10/site-packages/snowflake/connector/errors.py", line 210, in default_errorhandler
    raise error_class(
snowflake.connector.errors.OperationalError: 250003: 250003: Hit non-retryable SSL error, HTTPSConnectionPool(host='avcudfk-tl56570.ap_southeast_1.snowflakecomputing.com', port=443): Max retries exceeded with url: /session/v1/login-request?request_id=81c11043-deeb-48f2-8025-8d7aacb412cb&databaseName=AIRFLOW_DB&schemaName=PUBLIC&warehouse=AIRFLOW_WH&roleName=ACCOUNTADMIN&request_guid=7cd2ff1b-6590-46f5-983c-83280e431eb2 (Caused by SSLError(CertificateError("hostname 'avcudfk-tl56570.ap_southeast_1.snowflakecomputing.com' doesn't match either of '*.prod3.us-west-2.snowflakecomputing.com', '*.us-west-2.snowflakecomputing.com', '*.global.snowflakecomputing.com', '*.snowflakecomputing.com', '*.prod3.us-west-2.aws.snowflakecomputing.com'"))).
Verify that the hostnames and port numbers in SYSTEM$ALLOWLIST are added to your firewall's allowed list.
To further troubleshoot your connection you may reference the following article: https://docs.snowflake.com/en/user-guide/client-connectivity-troubleshooting/overview.

The above exception was the direct cause of the following exception:

Traceback (most recent call last):
  File "/home/pranav_shirali/airflow-project/airflow-env/lib/python3.10/site-packages/airflow/models/taskinstance.py", line 767, in _execute_task
    result = _execute_callable(context=context, **execute_callable_kwargs)
  File "/home/pranav_shirali/airflow-project/airflow-env/lib/python3.10/site-packages/airflow/models/taskinstance.py", line 733, in _execute_callable
    return ExecutionCallableRunner(
  File "/home/pranav_shirali/airflow-project/airflow-env/lib/python3.10/site-packages/airflow/utils/operator_helpers.py", line 252, in run
    return self.func(*args, **kwargs)
  File "/home/pranav_shirali/airflow-project/airflow-env/lib/python3.10/site-packages/airflow/models/baseoperator.py", line 406, in wrapper
    return func(self, *args, **kwargs)
  File "/home/pranav_shirali/airflow-project/airflow-env/lib/python3.10/site-packages/airflow/providers/common/sql/operators/sql.py", line 312, in execute
    output = hook.run(
  File "/home/pranav_shirali/airflow-project/airflow-env/lib/python3.10/site-packages/airflow/providers/snowflake/hooks/snowflake.py", line 515, in run
    with closing(self.get_conn()) as conn:
  File "/home/pranav_shirali/airflow-project/airflow-env/lib/python3.10/site-packages/airflow/providers/snowflake/hooks/snowflake.py", line 383, in get_conn
    conn = connector.connect(**conn_config)
  File "/home/pranav_shirali/airflow-project/airflow-env/lib/python3.10/site-packages/snowflake/connector/__init__.py", line 54, in Connect
    return SnowflakeConnection(**kwargs)
  File "/home/pranav_shirali/airflow-project/airflow-env/lib/python3.10/site-packages/snowflake/connector/connection.py", line 548, in __init__
    self.connect(**kwargs)
  File "/home/pranav_shirali/airflow-project/airflow-env/lib/python3.10/site-packages/snowflake/connector/connection.py", line 901, in connect
    self.__open_connection()
  File "/home/pranav_shirali/airflow-project/airflow-env/lib/python3.10/site-packages/snowflake/connector/connection.py", line 1293, in __open_connection
    self.authenticate_with_retry(self.auth_class)
  File "/home/pranav_shirali/airflow-project/airflow-env/lib/python3.10/site-packages/snowflake/connector/connection.py", line 1615, in authenticate_with_retry
    self._authenticate(auth_instance)
  File "/home/pranav_shirali/airflow-project/airflow-env/lib/python3.10/site-packages/snowflake/connector/connection.py", line 1693, in _authenticate
    raise auth_op from e
  File "/home/pranav_shirali/airflow-project/airflow-env/lib/python3.10/site-packages/snowflake/connector/connection.py", line 1668, in _authenticate
    auth_instance.handle_timeout(
  File "/home/pranav_shirali/airflow-project/airflow-env/lib/python3.10/site-packages/snowflake/connector/auth/by_plugin.py", line 211, in handle_timeout
    raise error
snowflake.connector.errors.OperationalError: 250001: 250001: Could not connect to Snowflake backend after 2 attempt(s).Aborting
Verify that the hostnames and port numbers in SYSTEM$ALLOWLIST are added to your firewall's allowed list.
To further troubleshoot your connection you may reference the following article: https://docs.snowflake.com/en/user-guide/client-connectivity-troubleshooting/overview.
[2025-05-23T11:27:34.510+0530] {taskinstance.py:1225} INFO - Marking task as FAILED. dag_id=elt_sales_stream_transformation, task_id=transform_sales_stream, run_id=manual__2025-05-23T05:57:27.667545+00:00, execution_date=20250523T055727, start_date=20250523T055730, end_date=20250523T055734
[2025-05-23T11:27:34.521+0530] {taskinstance.py:340} INFO - ::group::Post task execution logs
[2025-05-23T11:27:34.521+0530] {standard_task_runner.py:124} ERROR - Failed to execute job 165 for task transform_sales_stream (250001: 250001: Could not connect to Snowflake backend after 2 attempt(s).Aborting
Verify that the hostnames and port numbers in SYSTEM$ALLOWLIST are added to your firewall's allowed list.
To further troubleshoot your connection you may reference the following article: https://docs.snowflake.com/en/user-guide/client-connectivity-troubleshooting/overview.; 8813)
Traceback (most recent call last):
  File "/home/pranav_shirali/airflow-project/airflow-env/lib/python3.10/site-packages/snowflake/connector/vendored/urllib3/connectionpool.py", line 715, in urlopen
    httplib_response = self._make_request(
  File "/home/pranav_shirali/airflow-project/airflow-env/lib/python3.10/site-packages/snowflake/connector/vendored/urllib3/connectionpool.py", line 404, in _make_request
    self._validate_conn(conn)
  File "/home/pranav_shirali/airflow-project/airflow-env/lib/python3.10/site-packages/snowflake/connector/vendored/urllib3/connectionpool.py", line 1058, in _validate_conn
    conn.connect()
  File "/home/pranav_shirali/airflow-project/airflow-env/lib/python3.10/site-packages/snowflake/connector/vendored/urllib3/connection.py", line 472, in connect
    _match_hostname(cert, self.assert_hostname or server_hostname)
  File "/home/pranav_shirali/airflow-project/airflow-env/lib/python3.10/site-packages/snowflake/connector/vendored/urllib3/connection.py", line 545, in _match_hostname
    match_hostname(cert, asserted_hostname)
  File "/home/pranav_shirali/airflow-project/airflow-env/lib/python3.10/site-packages/snowflake/connector/vendored/urllib3/util/ssl_match_hostname.py", line 150, in match_hostname
    raise CertificateError(
snowflake.connector.vendored.urllib3.util.ssl_match_hostname.CertificateError: hostname 'avcudfk-tl56570.ap_southeast_1.snowflakecomputing.com' doesn't match either of '*.prod3.us-west-2.snowflakecomputing.com', '*.us-west-2.snowflakecomputing.com', '*.global.snowflakecomputing.com', '*.snowflakecomputing.com', '*.prod3.us-west-2.aws.snowflakecomputing.com'

During handling of the above exception, another exception occurred:

Traceback (most recent call last):
  File "/home/pranav_shirali/airflow-project/airflow-env/lib/python3.10/site-packages/snowflake/connector/vendored/requests/adapters.py", line 485, in send
    resp = conn.urlopen(
  File "/home/pranav_shirali/airflow-project/airflow-env/lib/python3.10/site-packages/snowflake/connector/vendored/urllib3/connectionpool.py", line 827, in urlopen
    return self.urlopen(
  File "/home/pranav_shirali/airflow-project/airflow-env/lib/python3.10/site-packages/snowflake/connector/vendored/urllib3/connectionpool.py", line 799, in urlopen
    retries = retries.increment(
  File "/home/pranav_shirali/airflow-project/airflow-env/lib/python3.10/site-packages/snowflake/connector/vendored/urllib3/util/retry.py", line 592, in increment
    raise MaxRetryError(_pool, url, error or ResponseError(cause))
snowflake.connector.vendored.urllib3.exceptions.MaxRetryError: HTTPSConnectionPool(host='avcudfk-tl56570.ap_southeast_1.snowflakecomputing.com', port=443): Max retries exceeded with url: /session/v1/login-request?request_id=81c11043-deeb-48f2-8025-8d7aacb412cb&databaseName=AIRFLOW_DB&schemaName=PUBLIC&warehouse=AIRFLOW_WH&roleName=ACCOUNTADMIN&request_guid=7cd2ff1b-6590-46f5-983c-83280e431eb2 (Caused by SSLError(CertificateError("hostname 'avcudfk-tl56570.ap_southeast_1.snowflakecomputing.com' doesn't match either of '*.prod3.us-west-2.snowflakecomputing.com', '*.us-west-2.snowflakecomputing.com', '*.global.snowflakecomputing.com', '*.snowflakecomputing.com', '*.prod3.us-west-2.aws.snowflakecomputing.com'")))

During handling of the above exception, another exception occurred:

Traceback (most recent call last):
  File "/home/pranav_shirali/airflow-project/airflow-env/lib/python3.10/site-packages/snowflake/connector/network.py", line 1091, in _request_exec
    raw_ret = session.request(
  File "/home/pranav_shirali/airflow-project/airflow-env/lib/python3.10/site-packages/snowflake/connector/vendored/requests/sessions.py", line 589, in request
    resp = self.send(prep, **send_kwargs)
  File "/home/pranav_shirali/airflow-project/airflow-env/lib/python3.10/site-packages/snowflake/connector/vendored/requests/sessions.py", line 703, in send
    r = adapter.send(request, **kwargs)
  File "/home/pranav_shirali/airflow-project/airflow-env/lib/python3.10/site-packages/snowflake/connector/vendored/requests/adapters.py", line 516, in send
    raise SSLError(e, request=request)
snowflake.connector.vendored.requests.exceptions.SSLError: HTTPSConnectionPool(host='avcudfk-tl56570.ap_southeast_1.snowflakecomputing.com', port=443): Max retries exceeded with url: /session/v1/login-request?request_id=81c11043-deeb-48f2-8025-8d7aacb412cb&databaseName=AIRFLOW_DB&schemaName=PUBLIC&warehouse=AIRFLOW_WH&roleName=ACCOUNTADMIN&request_guid=7cd2ff1b-6590-46f5-983c-83280e431eb2 (Caused by SSLError(CertificateError("hostname 'avcudfk-tl56570.ap_southeast_1.snowflakecomputing.com' doesn't match either of '*.prod3.us-west-2.snowflakecomputing.com', '*.us-west-2.snowflakecomputing.com', '*.global.snowflakecomputing.com', '*.snowflakecomputing.com', '*.prod3.us-west-2.aws.snowflakecomputing.com'")))

During handling of the above exception, another exception occurred:

Traceback (most recent call last):
  File "/home/pranav_shirali/airflow-project/airflow-env/lib/python3.10/site-packages/snowflake/connector/connection.py", line 1647, in _authenticate
    auth.authenticate(
  File "/home/pranav_shirali/airflow-project/airflow-env/lib/python3.10/site-packages/snowflake/connector/auth/_auth.py", line 226, in authenticate
    ret = self._rest._post_request(
  File "/home/pranav_shirali/airflow-project/airflow-env/lib/python3.10/site-packages/snowflake/connector/network.py", line 759, in _post_request
    ret = self.fetch(
  File "/home/pranav_shirali/airflow-project/airflow-env/lib/python3.10/site-packages/snowflake/connector/network.py", line 874, in fetch
    ret = self._request_exec_wrapper(
  File "/home/pranav_shirali/airflow-project/airflow-env/lib/python3.10/site-packages/snowflake/connector/network.py", line 1002, in _request_exec_wrapper
    raise e
  File "/home/pranav_shirali/airflow-project/airflow-env/lib/python3.10/site-packages/snowflake/connector/network.py", line 924, in _request_exec_wrapper
    return_object = self._request_exec(
  File "/home/pranav_shirali/airflow-project/airflow-env/lib/python3.10/site-packages/snowflake/connector/network.py", line 1161, in _request_exec
    Error.errorhandler_wrapper(
  File "/home/pranav_shirali/airflow-project/airflow-env/lib/python3.10/site-packages/snowflake/connector/errors.py", line 279, in errorhandler_wrapper
    handed_over = Error.hand_to_other_handler(
  File "/home/pranav_shirali/airflow-project/airflow-env/lib/python3.10/site-packages/snowflake/connector/errors.py", line 337, in hand_to_other_handler
    connection.errorhandler(connection, cursor, error_class, error_value)
  File "/home/pranav_shirali/airflow-project/airflow-env/lib/python3.10/site-packages/snowflake/connector/errors.py", line 210, in default_errorhandler
    raise error_class(
snowflake.connector.errors.OperationalError: 250003: 250003: Hit non-retryable SSL error, HTTPSConnectionPool(host='avcudfk-tl56570.ap_southeast_1.snowflakecomputing.com', port=443): Max retries exceeded with url: /session/v1/login-request?request_id=81c11043-deeb-48f2-8025-8d7aacb412cb&databaseName=AIRFLOW_DB&schemaName=PUBLIC&warehouse=AIRFLOW_WH&roleName=ACCOUNTADMIN&request_guid=7cd2ff1b-6590-46f5-983c-83280e431eb2 (Caused by SSLError(CertificateError("hostname 'avcudfk-tl56570.ap_southeast_1.snowflakecomputing.com' doesn't match either of '*.prod3.us-west-2.snowflakecomputing.com', '*.us-west-2.snowflakecomputing.com', '*.global.snowflakecomputing.com', '*.snowflakecomputing.com', '*.prod3.us-west-2.aws.snowflakecomputing.com'"))).
Verify that the hostnames and port numbers in SYSTEM$ALLOWLIST are added to your firewall's allowed list.
To further troubleshoot your connection you may reference the following article: https://docs.snowflake.com/en/user-guide/client-connectivity-troubleshooting/overview.

The above exception was the direct cause of the following exception:

Traceback (most recent call last):
  File "/home/pranav_shirali/airflow-project/airflow-env/lib/python3.10/site-packages/airflow/task/task_runner/standard_task_runner.py", line 117, in _start_by_fork
    ret = args.func(args, dag=self.dag)
  File "/home/pranav_shirali/airflow-project/airflow-env/lib/python3.10/site-packages/airflow/cli/cli_config.py", line 49, in command
    return func(*args, **kwargs)
  File "/home/pranav_shirali/airflow-project/airflow-env/lib/python3.10/site-packages/airflow/utils/cli.py", line 115, in wrapper
    return f(*args, **kwargs)
  File "/home/pranav_shirali/airflow-project/airflow-env/lib/python3.10/site-packages/airflow/cli/commands/task_command.py", line 483, in task_run
    task_return_code = _run_task_by_selected_method(args, _dag, ti)
  File "/home/pranav_shirali/airflow-project/airflow-env/lib/python3.10/site-packages/airflow/cli/commands/task_command.py", line 256, in _run_task_by_selected_method
    return _run_raw_task(args, ti)
  File "/home/pranav_shirali/airflow-project/airflow-env/lib/python3.10/site-packages/airflow/cli/commands/task_command.py", line 341, in _run_raw_task
    return ti._run_raw_task(
  File "/home/pranav_shirali/airflow-project/airflow-env/lib/python3.10/site-packages/airflow/utils/session.py", line 97, in wrapper
    return func(*args, session=session, **kwargs)
  File "/home/pranav_shirali/airflow-project/airflow-env/lib/python3.10/site-packages/airflow/models/taskinstance.py", line 3004, in _run_raw_task
    return _run_raw_task(
  File "/home/pranav_shirali/airflow-project/airflow-env/lib/python3.10/site-packages/airflow/models/taskinstance.py", line 273, in _run_raw_task
    TaskInstance._execute_task_with_callbacks(
  File "/home/pranav_shirali/airflow-project/airflow-env/lib/python3.10/site-packages/airflow/models/taskinstance.py", line 3158, in _execute_task_with_callbacks
    result = self._execute_task(context, task_orig)
  File "/home/pranav_shirali/airflow-project/airflow-env/lib/python3.10/site-packages/airflow/models/taskinstance.py", line 3182, in _execute_task
    return _execute_task(self, context, task_orig)
  File "/home/pranav_shirali/airflow-project/airflow-env/lib/python3.10/site-packages/airflow/models/taskinstance.py", line 767, in _execute_task
    result = _execute_callable(context=context, **execute_callable_kwargs)
  File "/home/pranav_shirali/airflow-project/airflow-env/lib/python3.10/site-packages/airflow/models/taskinstance.py", line 733, in _execute_callable
    return ExecutionCallableRunner(
  File "/home/pranav_shirali/airflow-project/airflow-env/lib/python3.10/site-packages/airflow/utils/operator_helpers.py", line 252, in run
    return self.func(*args, **kwargs)
  File "/home/pranav_shirali/airflow-project/airflow-env/lib/python3.10/site-packages/airflow/models/baseoperator.py", line 406, in wrapper
    return func(self, *args, **kwargs)
  File "/home/pranav_shirali/airflow-project/airflow-env/lib/python3.10/site-packages/airflow/providers/common/sql/operators/sql.py", line 312, in execute
    output = hook.run(
  File "/home/pranav_shirali/airflow-project/airflow-env/lib/python3.10/site-packages/airflow/providers/snowflake/hooks/snowflake.py", line 515, in run
    with closing(self.get_conn()) as conn:
  File "/home/pranav_shirali/airflow-project/airflow-env/lib/python3.10/site-packages/airflow/providers/snowflake/hooks/snowflake.py", line 383, in get_conn
    conn = connector.connect(**conn_config)
  File "/home/pranav_shirali/airflow-project/airflow-env/lib/python3.10/site-packages/snowflake/connector/__init__.py", line 54, in Connect
    return SnowflakeConnection(**kwargs)
  File "/home/pranav_shirali/airflow-project/airflow-env/lib/python3.10/site-packages/snowflake/connector/connection.py", line 548, in __init__
    self.connect(**kwargs)
  File "/home/pranav_shirali/airflow-project/airflow-env/lib/python3.10/site-packages/snowflake/connector/connection.py", line 901, in connect
    self.__open_connection()
  File "/home/pranav_shirali/airflow-project/airflow-env/lib/python3.10/site-packages/snowflake/connector/connection.py", line 1293, in __open_connection
    self.authenticate_with_retry(self.auth_class)
  File "/home/pranav_shirali/airflow-project/airflow-env/lib/python3.10/site-packages/snowflake/connector/connection.py", line 1615, in authenticate_with_retry
    self._authenticate(auth_instance)
  File "/home/pranav_shirali/airflow-project/airflow-env/lib/python3.10/site-packages/snowflake/connector/connection.py", line 1693, in _authenticate
    raise auth_op from e
  File "/home/pranav_shirali/airflow-project/airflow-env/lib/python3.10/site-packages/snowflake/connector/connection.py", line 1668, in _authenticate
    auth_instance.handle_timeout(
  File "/home/pranav_shirali/airflow-project/airflow-env/lib/python3.10/site-packages/snowflake/connector/auth/by_plugin.py", line 211, in handle_timeout
    raise error
snowflake.connector.errors.OperationalError: 250001: 250001: Could not connect to Snowflake backend after 2 attempt(s).Aborting
Verify that the hostnames and port numbers in SYSTEM$ALLOWLIST are added to your firewall's allowed list.
To further troubleshoot your connection you may reference the following article: https://docs.snowflake.com/en/user-guide/client-connectivity-troubleshooting/overview.
[2025-05-23T11:27:34.568+0530] {local_task_job_runner.py:266} INFO - Task exited with return code 1
[2025-05-23T11:27:34.577+0530] {taskinstance.py:3900} INFO - 0 downstream tasks scheduled from follow-on schedule check
[2025-05-23T11:27:34.577+0530] {local_task_job_runner.py:245} INFO - ::endgroup::
